<?xml version="1.0" ?>
<robot name="LV">
  <joint name="LV__link_0_JOINT_0" type="revolute">
    <parent link="LV__link_0"/>
    <child link="LV__link_1_clone"/>
    <origin rpy="0      1.5707  0" xyz="-0.06999  0.51724 -0.039"/>
    <axis xyz="-1.00000000e+00   0.00000000e+00   9.00000000e-05"/>
    <limit effort="-1.0" lower="-1.79769e+308" upper="1.79769e+308" velocity="10.0"/>
  </joint>
  <joint name="LV__link_0_JOINT_1" type="revolute">
    <parent link="LV__link_0"/>
    <child link="LV__link_1_clone_0"/>
    <origin rpy="0      1.5707  0" xyz="0.06999  0.51441 -0.039"/>
    <axis xyz="-1.00000000e+00   0.00000000e+00   9.00000000e-05"/>
    <limit effort="-1.0" lower="-1.79769e+308" upper="1.79769e+308" velocity="10.0"/>
  </joint>
  <joint name="LV__link_0_JOINT_2" type="revolute">
    <parent link="LV__link_0"/>
    <child link="LV__link_1"/>
    <origin rpy="0      1.5707  0" xyz="-0.06999 -0.53055 -0.039"/>
    <axis xyz="-1.00000000e+00   0.00000000e+00   9.00000000e-05"/>
    <limit effort="-1.0" lower="-1.79769e+308" upper="1.79769e+308" velocity="10.0"/>
  </joint>
  <joint name="LV__link_0_JOINT_3" type="revolute">
    <parent link="LV__link_0"/>
    <child link="LV__link_1_clone_1"/>
    <origin rpy="0      1.5707  0" xyz="0.06999 -0.53055 -0.039"/>
    <axis xyz="-1.00000000e+00   0.00000000e+00   9.00000000e-05"/>
    <limit effort="-1.0" lower="-1.79769e+308" upper="1.79769e+308" velocity="10.0"/>
  </joint>
  <link name="LV__link_0">
    <inertial>
      <mass value="1"/>
      <origin rpy="0  0  0" xyz="0  0  0"/>
      <inertia ixx="0.166667" ixy="0" ixz="0" iyy="0.166667" iyz="0" izz="0.166667"/>
    </inertial>
    <collision name="LV__collision">
      <origin rpy="0  0  0" xyz="0       0.02944  0.156"/>
      <geometry>
        <box size="0.18 1.2 0.35"/>
      </geometry>
    </collision>
    <visual name="LV__visual">
      <origin rpy="0  0  0" xyz="0       0.02944  0.156"/>
      <geometry>
        <box size="0.18 1.2 0.35"/>
      </geometry>
    </visual>
  </link>
  <link name="LV__link_1">
    <inertial>
      <mass value="1"/>
      <origin rpy="0  0  0" xyz="0  0  0"/>
      <inertia ixx="0.145833" ixy="0" ixz="0" iyy="0.145833" iyz="0" izz="0.125"/>
    </inertial>
    <collision name="LV__collision">
      <origin rpy="0  0  0" xyz="0  0  0"/>
      <geometry>
        <cylinder length="0.04" radius="0.04"/>
      </geometry>
    </collision>
    <visual name="LV__visual">
      <origin rpy="0  0  0" xyz="0  0  0"/>
      <geometry>
        <cylinder length="0.04" radius="0.04"/>
      </geometry>
    </visual>
  </link>
  <link name="LV__link_1_clone">
    <inertial>
      <mass value="1"/>
      <origin rpy="0  0  0" xyz="0  0  0"/>
      <inertia ixx="0.145833" ixy="0" ixz="0" iyy="0.145833" iyz="0" izz="0.125"/>
    </inertial>
    <collision name="LV__collision">
      <origin rpy="0  0  0" xyz="0  0  0"/>
      <geometry>
        <cylinder length="0.04" radius="0.04"/>
      </geometry>
    </collision>
    <visual name="LV__visual">
      <origin rpy="0  0  0" xyz="0  0  0"/>
      <geometry>
        <cylinder length="0.04" radius="0.04"/>
      </geometry>
    </visual>
  </link>
  <link name="LV__link_1_clone_0">
    <inertial>
      <mass value="1"/>
      <origin rpy="0  0  0" xyz="0  0  0"/>
      <inertia ixx="0.145833" ixy="0" ixz="0" iyy="0.145833" iyz="0" izz="0.125"/>
    </inertial>
    <collision name="LV__collision">
      <origin rpy="0  0  0" xyz="0  0  0"/>
      <geometry>
        <cylinder length="0.04" radius="0.04"/>
      </geometry>
    </collision>
    <visual name="LV__visual">
      <origin rpy="0  0  0" xyz="0  0  0"/>
      <geometry>
        <cylinder length="0.04" radius="0.04"/>
      </geometry>
    </visual>
  </link>
  <link name="LV__link_1_clone_1">
    <inertial>
      <mass value="1"/>
      <origin rpy="0  0  0" xyz="0  0  0"/>
      <inertia ixx="0.145833" ixy="0" ixz="0" iyy="0.145833" iyz="0" izz="0.125"/>
    </inertial>
    <collision name="LV__collision">
      <origin rpy="0  0  0" xyz="0  0  0"/>
      <geometry>
        <cylinder length="0.04" radius="0.04"/>
      </geometry>
    </collision>
    <visual name="LV__visual">
      <origin rpy="0  0  0" xyz="0  0  0"/>
      <geometry>
        <cylinder length="0.04" radius="0.04"/>
      </geometry>
    </visual>
  </link>
</robot>
