<?xml version="1.0" ?>
<robot name="LV" xmlns:xacro="http://www.ros.org/wiki/xacro">

  <xacro:include filename="$(find platooning_tracking_gazebo)/models/LV/model.gazebo" />
  <xacro:include filename="$(find platooning_tracking_gazebo)/models/LV/materials.xacro" />

  <!-- Joint -->
  <!-- front -->
  <joint name="front_left" type="continuous">
    <parent link="LV__link_0"/>
    <child link="LV__link_1_clone"/>
    <origin rpy="0      1.5707  0" xyz="-0.06999  0.51724 -0.039"/>
    <axis xyz="0 0 -1"/>
    <dynamics damping="0.7"/>
    <limit effort="100" velocity="100"/>
  </joint>
  <joint name="front_right" type="continuous">
    <parent link="LV__link_0"/>
    <child link="LV__link_1_clone_0"/>
    <origin rpy="0      1.5707  0" xyz="0.06999  0.51441 -0.039"/>
    <axis xyz="0 0 -1"/>
    <dynamics damping="0.7"/>
    <limit effort="100" velocity="100"/>
  </joint>

  <!-- rear -->
  <joint name="rear_left" type="continuous">
    <parent link="LV__link_0"/>
    <child link="LV__link_1"/>
    <origin rpy="0      1.5707  0" xyz="-0.06999 -0.53055 -0.039"/>
    <axis xyz="0 0 -1"/>
    <dynamics damping="0.7"/>
    <limit effort="10" velocity="100"/>
  </joint>
  <joint name="rear_right" type="continuous">
    <parent link="LV__link_0"/>
    <child link="LV__link_1_clone_1"/>
    <origin rpy="0      1.5707  0" xyz="0.06999 -0.53055 -0.039"/>
    <axis xyz="0 0 -1"/>
    <dynamics damping="0.7"/>
    <limit effort="10" velocity="100"/>
  </joint>

  <!-- Link -->
  <link name="LV__link_0">
    <inertial>
      <mass value="1"/>
      <origin rpy="0  0  0" xyz="0  0  0"/>
      <inertia ixx="0.166667" ixy="0" ixz="0" iyy="0.166667" iyz="0" izz="0.166667"/>
    </inertial>
    <collision name="LV__collision">
      <origin rpy="0  0  0" xyz="0       0.02944  0.156"/>
      <geometry>
        <box size="0.18 1.2 0.35"/>
      </geometry>
    </collision>
    <visual name="LV__visual">
      <origin rpy="0  0  0" xyz="0       0.02944  0.156"/>
      <geometry>
        <box size="0.18 1.2 0.35"/>
      </geometry>
    </visual>
  </link>
  <link name="LV__link_1">
    <inertial>
      <mass value="1"/>
      <origin rpy="0  0  0" xyz="0  0  0"/>
      <inertia ixx="0.145833" ixy="0" ixz="0" iyy="0.145833" iyz="0" izz="0.125"/>
    </inertial>
    <collision name="LV__collision">
      <origin rpy="0  0  0" xyz="0  0  0"/>
      <geometry>
        <cylinder length="0.04" radius="0.04"/>
      </geometry>
    </collision>
    <visual name="LV__visual">
      <origin rpy="0  0  0" xyz="0  0  0"/>
      <geometry>
        <cylinder length="0.04" radius="0.04"/>
      </geometry>
    </visual>
  </link>
  <link name="LV__link_1_clone">
    <inertial>
      <mass value="1"/>
      <origin rpy="0  0  0" xyz="0  0  0"/>
      <inertia ixx="0.145833" ixy="0" ixz="0" iyy="0.145833" iyz="0" izz="0.125"/>
    </inertial>
    <collision name="LV__collision">
      <origin rpy="0  0  0" xyz="0  0  0"/>
      <geometry>
        <cylinder length="0.04" radius="0.04"/>
      </geometry>
    </collision>
    <visual name="LV__visual">
      <origin rpy="0  0  0" xyz="0  0  0"/>
      <geometry>
        <cylinder length="0.04" radius="0.04"/>
      </geometry>
    </visual>
  </link>
  <link name="LV__link_1_clone_0">
    <inertial>
      <mass value="1"/>
      <origin rpy="0  0  0" xyz="0  0  0"/>
      <inertia ixx="0.145833" ixy="0" ixz="0" iyy="0.145833" iyz="0" izz="0.125"/>
    </inertial>
    <collision name="LV__collision">
      <origin rpy="0  0  0" xyz="0  0  0"/>
      <geometry>
        <cylinder length="0.04" radius="0.04"/>
      </geometry>
    </collision>
    <visual name="LV__visual">
      <origin rpy="0  0  0" xyz="0  0  0"/>
      <geometry>
        <cylinder length="0.04" radius="0.04"/>
      </geometry>
    </visual>
  </link>
  <link name="LV__link_1_clone_1">
    <inertial>
      <mass value="1"/>
      <origin rpy="0  0  0" xyz="0  0  0"/>
      <inertia ixx="0.145833" ixy="0" ixz="0" iyy="0.145833" iyz="0" izz="0.125"/>
    </inertial>
    <collision name="LV__collision">
      <origin rpy="0  0  0" xyz="0  0  0"/>
      <geometry>
        <cylinder length="0.04" radius="0.04"/>
      </geometry>
    </collision>
    <visual name="LV__visual">
      <origin rpy="0  0  0" xyz="0  0  0"/>
      <geometry>
        <cylinder length="0.04" radius="0.04"/>
      </geometry>
    </visual>
  </link>

  <transmission name="tran1">
    <type>transmission_interface/SimpleTransmission</type>
    <joint name="front_left">
      <hardwareInterface>hardware_interface/EffortJointInterface</hardwareInterface>
    </joint>
    <actuator name="motor1">
      <hardwareInterface>hardware_interface/EffortJointInterface</hardwareInterface>
      <mechanicalReduction>1</mechanicalReduction>
    </actuator>
  </transmission>

  <transmission name="tran2">
    <type>transmission_interface/SimpleTransmission</type>
    <joint name="front_right">
      <hardwareInterface>hardware_interface/EffortJointInterface</hardwareInterface>
    </joint>
    <actuator name="motor2">
      <hardwareInterface>hardware_interface/EffortJointInterface</hardwareInterface>
      <mechanicalReduction>1</mechanicalReduction>
    </actuator>
  </transmission>



</robot>
